@log_function_call
def checked_call(command, quiet=False, logoutput=None, stdout=subprocess.PIPE, stderr=subprocess.STDOUT, cwd=None, env=None, preexec_fn=preexec_fn, user=None, wait_for_finish=True, timeout=None, on_timeout=None, path=None, sudo=False, on_new_line=None, tries=1, try_sleep=0):
    '\n  Execute the shell command and throw an exception on failure.\n  @throws Fail\n  @return: return_code, output\n  '
    return _call_wrapper(command, logoutput=logoutput, throw_on_failure=True, stdout=stdout, stderr=stderr, cwd=cwd, env=env, preexec_fn=preexec_fn, user=user, wait_for_finish=wait_for_finish, on_timeout=on_timeout, timeout=timeout, path=path, sudo=sudo, on_new_line=on_new_line, tries=tries, try_sleep=try_sleep)
